Workbook

Sheet Instructions
B1: Sleep Diary Instructions
C3: This Sleep Diary will help you track your sleep, allowing you to see habits and trends that are helping you sleep or that can be improved. This diary is designed for someone with experience using spreadsheets. If you are not comfortable using spreadsheets, you should use another Sleep Diary.
C6: Tips for using the Spreadsheet Sleep Diary
C8: ="- The Sleep Diary is designed to complement The Path to Better Sleep Course." -> - The Sleep Diary is designed to complement The Path to Better Sleep Course.
C9: ="- Complete each week of the Sleep Diary as you progress through each week of the course." -> - Complete each week of the Sleep Diary as you progress through each week of the course.
C10: ="- This Sleep Diary only takes a few minutes each day to complete." -> - This Sleep Diary only takes a few minutes each day to complete.
C11: ="- Times can be approximate. Do your best; it will get easier." -> - Times can be approximate. Do your best; it will get easier.
C12: ="- Establish (or set) a time to enter your data every day." -> - Establish (or set) a time to enter your data every day.
C13: ="- All times are in military time. You must type the colon in between the hour and minutes. " -> - All times are in military time. You must type the colon in between the hour and minutes.
C14: ="- Complete every cell for each day. Skipping a cell can cause the calculations not to work correctly." -> - Complete every cell for each day. Skipping a cell can cause the calculations not to work correctly.
C15: ="- This icon ( ) indicates the cell has additional information. Hover your mouse over it for explanations about the cell." -> - This icon ( ) indicates the cell has additional information. Hover your mouse over it for explanations about the cell.
C17: How to use the Spreadsheet Sleep Diary
C19: Week 1
C20: ="- Select the Week 1 tab." -> - Select the Week 1 tab.
C21: ="- Begin entering your sleep data in Day 1." -> - Begin entering your sleep data in Day 1.
C22: ="- Return every day and complete that day in the diary." -> - Return every day and complete that day in the diary.
C23: ="- Once you have completed 5-7 days, advance to Week 2 to calculate your Sleep Prescription." -> - Once you have completed 5-7 days, advance to Week 2 to calculate your Sleep Prescription.
C25: Week 2
C26: ="- Before you begin entering Week 2 information, calculate your Sleep Prescription." -> - Before you begin entering Week 2 information, calculate your Sleep Prescription.
C27: ="- To calculate your Sleep Prescription, all you need to do is enter your Wake Time." -> - To calculate your Sleep Prescription, all you need to do is enter your Wake Time.
C28: ="-- Select a Wake Time that works for you every day of the week, including weekends. " -> -- Select a Wake Time that works for you every day of the week, including weekends.
C29: ="-- Your Wake Time should allow you enough time to wake up and meet your daily obligations — work, school, gym time, etc." -> -- Your Wake Time should allow you enough time to wake up and meet your daily obligations — work, school, gym time, etc.
C30: ="- Complete your Sleep Diary the same way you did in Week 1." -> - Complete your Sleep Diary the same way you did in Week 1.
C31: ="- Once you have completed 5-7 days, advance to Week 3 to modify your Sleep Prescription." -> - Once you have completed 5-7 days, advance to Week 3 to modify your Sleep Prescription.
C33: Weeks 3 - 6
C34: ="- Before you begin entering data each week, modify your Sleep Prescription." -> - Before you begin entering data each week, modify your Sleep Prescription.
C35: ="-- To modify your Sleep Prescription, answer the questions on the top of the page under Adjust Your Sleep Prescription. " -> -- To modify your Sleep Prescription, answer the questions on the top of the page under Adjust Your Sleep Prescription.
C36: ="-- Based on how you answer the questions and your Sleep Efficiency from the previous week your Earliest Bedtime may change." -> -- Based on how you answer the questions and your Sleep Efficiency from the previous week your Earliest Bedtime may change.
C37: ="- Once you have completed 5-7 days, you can advance to the next week." -> - Once you have completed 5-7 days, you can advance to the next week.
C40: Frequently Asked Questions
C42: Why are the calculated times are displayed as ###### ?
C43: =" - Microsoft Excel supports two different date systems. These systems are the 1900 date system and the 1904 date system. For the diary to work correctly it should be set to the 1904 date system." -> - Microsoft Excel supports two different date systems. These systems are the 1900 date system and the 1904 date system. For the diary to work correctly it should be set to the 1904 date system.
C44: ="-- To learn more about this error or to change your date system click here." -> -- To learn more about this error or to change your date system click here.

Sheet Week 1
B1: Week 1
C3: Sleep Diary Entry for Week 1 | E3: Sample | F3: Day 1 | G3: Day 2 | H3: Day 3 | I3: Day 4 | J3: Day 5 | K3: Day 6 | L3: Day 7
C4: 1. | D4: Date | E4: 40544 | F4: 39405
C5: 2. | D5: How long did you nap or doze yesterday (in minutes)? | E5: 30
C6: 3. | D6: What time did you get into bed yesterday? | E6: 0.97916667 | F6: 0.97916667
C7: 4. | D7: What time did you try to go to sleep? | E7: 0.98958333 | F7: 0.97916667
C8: 5. | D8: How long did it actually take you to fall asleep (in minutes)? | E8: 30 | F8: 2
C9: 6. | D9: How many times did you wake up during the night? | E9: 2 | F9: 5
C10: 7. | D10: In total, how long did these awakening last (in minutes)? | E10: 60
C11: 8. | D11: What time was your final awakening? | E11: 0.29166667 | F11: 0.27083333
C12: 9. | D12: When did you get out of bed to start your day? | E12: 0.33333333 | F12: 6.3
C13: 10. | D13: How much earlier did you wakeup than desired (in minutes)? | E13: 30 | F13: 0
C14: 11. | D14: How would you rate the quality of your sleep? | E14: Fair | F14: Fair
D15: Goal | E15: 0.85 | F15: 0.85 | G15: 0.85 | H15: 0.85 | I15: 0.85 | J15: 0.85 | K15: 0.85 | L15: 0.85
C16: Calculated Results
D17: Time in Bed (in Hours and Minutes h:mm) | E17: =calculations!D24 -> 0.34375 | F17: =calculations!E24 -> 5.3208333 | G17: =calculations!F24 -> 0 | H17: =calculations!G24 -> 0 | I17: =calculations!H24 -> 0 | J17: =calculations!I24 -> 0 | K17: =calculations!J24 -> 0 | L17: =calculations!K24 -> 0
D18: Total Sleep Time (in Hours and Minutes h:mm) | E18: =calculations!D25 -> 0.23958333 | F18: =calculations!E25 -> 5.2902778 | G18: =calculations!F25 -> 0 | H18: =calculations!G25 -> 0 | I18: =calculations!H25 -> 0 | J18: =calculations!I25 -> 0 | K18: =calculations!J25 -> 0 | L18: =calculations!K25 -> 0
D19: Sleep Efficiency | E19: =calculations!D26 -> 0.6969697 | F19: =calculations!E26 -> 0.99425737 | G19: =calculations!F26 | H19: =calculations!G26 | I19: =calculations!H26 | J19: =calculations!I26 | K19: =calculations!J26 | L19: =calculations!K26
C22: WEEKLY AVERAGES (Will not populate until you have at least 5 sleep diary entries)
D23: Average time napping | E23: =calculations!D30
D24: Average time you got into bed | E24: =calculations!D31
D25: Average time you tried to go to sleep | E25: =calculations!D32
D26: Average time it actually took you to fall asleep | E26: =calculations!D33
D27: Average time of your final awakening | E27: =calculations!D34
D28: Average time you got out of bed to start your day | E28: =calculations!D35
D29: Average time sleeping | E29: =calculations!D36
D30: Average sleep efficiency | E30: =calculations!D37

Sheet Week 2
B1: Week 2
C3: Calculate your Sleep Prescription*
C4: 1. Enter your Wake Time for the week (in military time h:mm). | E4: 0.16666667
C5: 2. Your Sleep Prescription will be calculated for you:
D6: Maximum Time Allowed in Bed (in Hours and Minutes h:mm). | E6: =IFERROR(calculations!T43, "*Error in calculation") -> *Error in calculation | F6: =IF(E6<=0.229166666666667,"<< Do not decrease your time in bed to under 5 ½ hours (330 Minutes). ","")
D7: Your Earliest Bedtime (in military time hh:mm) | E7: =IFERROR(calculations!S46, "*Error in calculation") -> *Error in calculation
D8: Your average Sleep Efficiency from week 1: | E8: ='Week 1'!E30
C9: *NOTE: This calculator will not work until you have at least 5 sleep diary entries in the previous week
C12: Sleep Diary Entry for Week 2 | D12: Sleep Diary Entry for Week 2 | E12: Sample | F12: Day 1 | G12: Day 2 | H12: Day 3 | I12: Day 4 | J12: Day 5 | K12: Day 6 | L12: Day 7
C13: 1. | D13: Date | E13: 41647
C14: 2. | D14: How long did you nap or doze yesterday (in minutes)? | E14: 30
C15: 3. | D15: What time did you get into bed yesterday? | E15: 0.97916667
C16: 4. | D16: What time did you try to go to sleep? | E16: 0.98958333
C17: 5. | D17: How long did it actually take you to fall asleep (in minutes)? | E17: 30
C18: 6. | D18: How many times did you wake up during the night? | E18: 2
C19: 7. | D19: In total, how long did these awakening last (in minutes)? | E19: 60
C20: 8. | D20: What time was your final awakening? | E20: 0.29166667
C21: 9. | D21: When did you get out of bed to start your day? | E21: 0.33333333
C22: 10. | D22: How long did you wakeup earlier than desired (in minutes)? | E22: 30
C23: 11. | D23: How would you rate the quality of your sleep? | E23: Fair
D24: Goal | E24: 0.85 | F24: 0.85 | G24: 0.85 | H24: 0.85 | I24: 0.85 | J24: 0.85 | K24: 0.85 | L24: 0.85
C25: Calculated Results
D26: Time in Bed | E26: =calculations!D59 -> 0.34375 | F26: =calculations!E59 -> 0 | G26: =calculations!F59 -> 0 | H26: =calculations!G59 -> 0 | I26: =calculations!H59 -> 0 | J26: =calculations!I59 -> 0 | K26: =calculations!J59 -> 0 | L26: =calculations!K59 -> 0
D27: Total Sleep Time | E27: =calculations!D60 -> 0.23958333 | F27: =calculations!E60 -> 0 | G27: =calculations!F60 -> 0 | H27: =calculations!G60 -> 0 | I27: =calculations!H60 -> 0 | J27: =calculations!I60 -> 0 | K27: =calculations!J60 -> 0 | L27: =calculations!K60 -> 0
D28: Sleep Efficiency | E28: =calculations!D61 -> 0.6969697 | F28: =calculations!E61 | G28: =calculations!F61 | H28: =calculations!G61 | I28: =calculations!H61 | J28: =calculations!I61 | K28: =calculations!J61 | L28: =calculations!K61
C31: WEEKLY AVERAGES (Will not populate until you have at least 5 sleep diary entries)
D32: Average time napping | E32: =calculations!D65
D33: Average time you got into bed | E33: =calculations!D66
D34: Average time you tried to go to sleep | E34: =calculations!D67
D35: Average time it actually took you to fall asleep | E35: =calculations!D68
D36: Average time of your final awakening | E36: =calculations!D69
D37: Average time you got out of bed to start your day | E37: =calculations!D70
D38: Average time sleeping | E38: =calculations!D71
D39: Average sleep efficiency | E39: =calculations!D72

Sheet Week 3
B1: Week 3
C3: Adjust your Sleep Prescription*
C4: 1. | D4: Answer the following questions:
D5: (1) Did you feel tired or fatigued during the day or evening? | E5: Never
D6: (2) Were you sleepy or drowsy during the day or evening? | E6: Never
D7: (3) Did you take any naps or fall asleep briefly during the day or evening? | E7: Never
D8: (4) Do you feel you have been getting an adequate amount of sleep? | E8: Never
C10: 2. | D10: Your Sleep Prescription adjustment will be calculated for you:
D11: Your average Sleep Efficiency from week 2: | E11: =IFERROR('Week 2'!E39, "*Error in calculation")
D12: Your Sleep Prescription adjustment: | E12: =calculations!S97 -> Do not change your Time in Bed
D13: Your new Maximum Time Allowed in Bed (in Hours and Minutes h:mm): | E13: =IFERROR(calculations!T104, "*Error in calculation") -> *Error in calculation | F13: =IF(E13<=0.229166666666667,"<< Do not decrease your time in bed to under 5 ½ hours (330 Minutes). ","")
D14: Your new Earliest Bedtime (in military time hh:mm): | E14: =IFERROR(calculations!S107, "*Error in calculation") -> *Error in calculation
C15: *NOTE: This calculator will not work until you have at least 5 sleep diary entries in the previous week
C18: Sleep Diary Entry for Week 3 | D18: Sleep Diary Entry for Week 3 | E18: Sample | F18: Day 1 | G18: Day 2 | H18: Day 3 | I18: Day 4 | J18: Day 5 | K18: Day 6 | L18: Day 7
C19: 1. | D19: Date | E19: 40544
C20: 2. | D20: How long did you nap or doze yesterday (in minutes)? | E20: 30
C21: 3. | D21: What time did you get into bed yesterday? | E21: 0.97916667
C22: 4. | D22: What time did you try to go to sleep? | E22: 0.98958333
C23: 5. | D23: How long did it actually take you to fall asleep (in minutes)? | E23: 30
C24: 6. | D24: How many times did you wake up during the night? | E24: 2
C25: 7. | D25: In total, how long did these awakening last (in minutes)? | E25: 60
C26: 8. | D26: What time was your final awakening? | E26: 0.29166667
C27: 9. | D27: When did you get out of bed to start your day? | E27: 0.33333333
C28: 10. | D28: How long did you wakeup earlier than desired (in minutes)? | E28: 30
C29: 11. | D29: How would you rate the quality of your sleep? | E29: Fair
D30: Goal | E30: 0.85 | F30: 0.85 | G30: 0.85 | H30: 0.85 | I30: 0.85 | J30: 0.85 | K30: 0.85 | L30: 0.85
C31: Calculated Results
D32: Time in Bed | E32: =calculations!D94 -> 0.34375 | F32: =calculations!E94 -> 0 | G32: =calculations!F94 -> 0 | H32: =calculations!G94 -> 0 | I32: =calculations!H94 -> 0 | J32: =calculations!I94 -> 0 | K32: =calculations!J94 -> 0 | L32: =calculations!K94 -> 0
D33: Total Sleep Time | E33: =calculations!D95 -> 0.23958333 | F33: =calculations!E95 -> 0 | G33: =calculations!F95 -> 0 | H33: =calculations!G95 -> 0 | I33: =calculations!H95 -> 0 | J33: =calculations!I95 -> 0 | K33: =calculations!J95 -> 0 | L33: =calculations!K95 -> 0
D34: Sleep Efficiency | E34: =calculations!D96 -> 0.6969697 | F34: =calculations!E96 | G34: =calculations!F96 | H34: =calculations!G96 | I34: =calculations!H96 | J34: =calculations!I96 | K34: =calculations!J96 | L34: =calculations!K96
C37: WEEKLY AVERAGES (Will not populate until you have at least 5 sleep diary entries)
D38: Average time napping | E38: =calculations!D100
D39: Average time you got into bed | E39: =calculations!D101
D40: Average time you tried to go to sleep | E40: =calculations!D102
D41: Average time it actually took you to fall asleep | E41: =calculations!D103
D42: Average time of your final awakening | E42: =calculations!D104
D43: Average time you got out of bed to start your day | E43: =calculations!D105
D44: Average time sleeping | E44: =calculations!D106
D45: Average sleep efficiency | E45: =calculations!D107

Sheet Week 4
B1: Week 4
C3: Adjust your Sleep Prescription* | D3: Adjust your Sleep Prescription*
C4: 1. | D4: Answer the following questions:
D5: (1) Did you feel tired or fatigued during the day or evening? | E5: Never
D6: (2) Were you sleepy or drowsy during the day or evening? | E6: Never
D7: (3) Did you take any naps or fall asleep briefly during the day or evening? | E7: Never
D8: (4) Do you feel you have been getting an adequate amount of sleep? | E8: Never
C10: 2. | D10: Your Sleep Prescription adjustment will be calculated for you:
D11: Your average Sleep Efficiency from week 3: | E11: =IFERROR('Week 3'!E45, "*Error in calculation")
D12: Your Sleep Prescription adjustment: | E12: =calculations!S133 -> Do not change your Time in Bed
D13: Your new Maximum Time Allowed in Bed (in Hours and Minutes h:mm): | E13: =IFERROR(calculations!T140, "*Error in calculation") -> *Error in calculation | F13: =IF(E13<=0.229166666666667,"<< Do not decrease your time in bed to under 5 ½ hours (330 Minutes). ","")
D14: Your new Earliest Bedtime (in military time hh:mm): | E14: =IFERROR(calculations!S143, "*Error in calculation") -> *Error in calculation
C15: *NOTE: This calculator will not work until you have at least 5 sleep diary entries in the previous week
C18: Sleep Diary Entry for Week 4 | D18: Sleep Diary Entry for Week 4 | E18: Sample | F18: Day 1 | G18: Day 2 | H18: Day 3 | I18: Day 4 | J18: Day 5 | K18: Day 6 | L18: Day 7
C19: 1. | D19: Date | E19: 40544
C20: 2. | D20: How long did you nap or doze yesterday (in minutes)? | E20: 30
C21: 3. | D21: What time did you get into bed yesterday? | E21: 0.97916667
C22: 4. | D22: What time did you try to go to sleep? | E22: 0.98958333
C23: 5. | D23: How long did it actually take you to fall asleep (in minutes)? | E23: 30
C24: 6. | D24: How many times did you wake up during the night? | E24: 2
C25: 7. | D25: In total, how long did these awakening last (in minutes)? | E25: 60
C26: 8. | D26: What time was your final awakening? | E26: 0.29166667
C27: 9. | D27: When did you get out of bed to start your day? | E27: 0.33333333
C28: 10. | D28: How long did you wakeup earlier than desired (in minutes)? | E28: 30
C29: 11. | D29: How would you rate the quality of your sleep? | E29: Fair
D30: Goal | E30: 0.85 | F30: 0.85 | G30: 0.85 | H30: 0.85 | I30: 0.85 | J30: 0.85 | K30: 0.85 | L30: 0.85
C31: Calculated Results
D32: Time in Bed | E32: =calculations!D130 -> 0.34375 | F32: =calculations!E130 -> 0 | G32: =calculations!F130 -> 0 | H32: =calculations!G130 -> 0 | I32: =calculations!H130 -> 0 | J32: =calculations!I130 -> 0 | K32: =calculations!J130 -> 0 | L32: =calculations!K130 -> 0
D33: Total Sleep Time | E33: =calculations!D131 -> 0.23958333 | F33: =calculations!E131 -> 0 | G33: =calculations!F131 -> 0 | H33: =calculations!G131 -> 0 | I33: =calculations!H131 -> 0 | J33: =calculations!I131 -> 0 | K33: =calculations!J131 -> 0 | L33: =calculations!K131 -> 0
D34: Sleep Efficiency | E34: =calculations!D132 -> 0.6969697 | F34: =calculations!E132 | G34: =calculations!F132 | H34: =calculations!G132 | I34: =calculations!H132 | J34: =calculations!I132 | K34: =calculations!J132 | L34: =calculations!K132
C37: WEEKLY AVERAGES (Will not populate until you have at least 5 sleep diary entries)
D38: Average time napping | E38: =calculations!D136
D39: Average time you got into bed | E39: =calculations!D137
D40: Average time you tried to go to sleep | E40: =calculations!D138
D41: Average time it actually took you to fall asleep | E41: =calculations!D139
D42: Average time of your final awakening | E42: =calculations!D140
D43: Average time you got out of bed to start your day | E43: =calculations!D141
D44: Average time sleeping | E44: =calculations!D142
D45: Average sleep efficiency | E45: =calculations!D143

Sheet Week 5
B1: Week 5
C3: Adjust your Sleep Prescription* | D3: Adjust your Sleep Prescription*
C4: 1. | D4: Answer the following questions:
D5: (1) Did you feel tired or fatigued during the day or evening? | E5: Never
D6: (2) Were you sleepy or drowsy during the day or evening? | E6: Never
D7: (3) Did you take any naps or fall asleep briefly during the day or evening? | E7: Never
D8: (4) Do you feel you have been getting an adequate amount of sleep? | E8: Never
C10: 2. | D10: Your Sleep Prescription adjustment will be calculated for you:
D11: Your average Sleep Efficiency from week 4: | E11: =IFERROR('Week 4'!E45, "*Error in calculation")
D12: Your Sleep Prescription adjustment: | E12: =calculations!S169 -> Do not change your Time in Bed
D13: Your new Maximum Time Allowed in Bed (in Hours and Minutes h:mm): | E13: =IFERROR(calculations!T176, "*Error in calculation") -> *Error in calculation | F13: =IF(E13<=0.229166666666667,"<< Do not decrease your time in bed to under 5 ½ hours (330 Minutes). ","")
D14: Your new Earliest Bedtime (in military time hh:mm): | E14: =IFERROR(calculations!S179, "*Error in calculation") -> *Error in calculation
C15: *NOTE: This calculator will not work until you have at least 5 sleep diary entries in the previous week
C18: Sleep Diary Entry for Week 5 | D18: Sleep Diary Entry for Week 5 | E18: Sample | F18: Day 1 | G18: Day 2 | H18: Day 3 | I18: Day 4 | J18: Day 5 | K18: Day 6 | L18: Day 7
C19: 1. | D19: Date | E19: 40544
C20: 2. | D20: How long did you nap or doze yesterday (in minutes)? | E20: 30
C21: 3. | D21: What time did you get into bed yesterday? | E21: 0.97916667
C22: 4. | D22: What time did you try to go to sleep? | E22: 0.98958333
C23: 5. | D23: How long did it actually take you to fall asleep (in minutes)? | E23: 30
C24: 6. | D24: How many times did you wake up during the night? | E24: 2
C25: 7. | D25: In total, how long did these awakening last (in minutes)? | E25: 60
C26: 8. | D26: What time was your final awakening? | E26: 0.29166667
C27: 9. | D27: When did you get out of bed to start your day? | E27: 0.33333333
C28: 10. | D28: How long did you wakeup earlier than desired (in minutes)? | E28: 30
C29: 11. | D29: How would you rate the quality of your sleep? | E29: Fair
D30: Goal | E30: 0.85 | F30: 0.85 | G30: 0.85 | H30: 0.85 | I30: 0.85 | J30: 0.85 | K30: 0.85 | L30: 0.85
C31: Calculated Results
D32: Time in Bed | E32: =calculations!D166 -> 0.34375 | F32: =calculations!E166 -> 0 | G32: =calculations!F166 -> 0 | H32: =calculations!G166 -> 0 | I32: =calculations!H166 -> 0 | J32: =calculations!I166 -> 0 | K32: =calculations!J166 -> 0 | L32: =calculations!K166 -> 0
D33: Total Sleep Time | E33: =calculations!D167 -> 0.23958333 | F33: =calculations!E167 -> 0 | G33: =calculations!F167 -> 0 | H33: =calculations!G167 -> 0 | I33: =calculations!H167 -> 0 | J33: =calculations!I167 -> 0 | K33: =calculations!J167 -> 0 | L33: =calculations!K167 -> 0
D34: Sleep Efficiency | E34: =calculations!D168 -> 0.6969697 | F34: =calculations!E168 | G34: =calculations!F168 | H34: =calculations!G168 | I34: =calculations!H168 | J34: =calculations!I168 | K34: =calculations!J168 | L34: =calculations!K168
C37: WEEKLY AVERAGES (Will not populate until you have at least 5 sleep diary entries)
D38: Average time napping | E38: =calculations!D172
D39: Average time you got into bed | E39: =calculations!D173
D40: Average time you tried to go to sleep | E40: =calculations!D174
D41: Average time it actually took you to fall asleep | E41: =calculations!D175
D42: Average time of your final awakening | E42: =calculations!D176
D43: Average time you got out of bed to start your day | E43: =calculations!D177
D44: Average time sleeping | E44: =calculations!D178
D45: Average sleep efficiency | E45: =calculations!D179

Sheet Week 6
B1: Week 6
C3: Adjust your Sleep Prescription* | D3: Adjust your Sleep Prescription*
C4: 1. | D4: Answer the following questions:
D5: (1) Did you feel tired or fatigued during the day or evening? | E5: Never
D6: (2) Were you sleepy or drowsy during the day or evening? | E6: Never
D7: (3) Did you take any naps or fall asleep briefly during the day or evening? | E7: Never
D8: (4) Do you feel you have been getting an adequate amount of sleep? | E8: Never
C10: 2. | D10: Your Sleep Prescription adjustment will be calculated for you:
D11: Your average Sleep Efficiency from week 5: | E11: =IFERROR('Week 5'!E45, "*Error in calculation")
D12: Your Sleep Prescription adjustment: | E12: =calculations!S205 -> Do not change your Time in Bed
D13: Your new Maximum Time Allowed in Bed (in Hours and Minutes h:mm): | E13: =IFERROR(calculations!T212, "*Error in calculation") -> *Error in calculation | F13: =IF(E13<=0.229166666666667,"<< Do not decrease your time in bed to under 5 ½ hours (330 Minutes). ","")
D14: Your new Earliest Bedtime (in military time hh:mm): | E14: =IFERROR(calculations!S215, "*Error in calculation") -> *Error in calculation
C15: *NOTE: This calculator will not work until you have at least 5 sleep diary entries in the previous week
D18: Sleep Diary Entry for Week 6 | E18: Sample | F18: Day 1 | G18: Day 2 | H18: Day 3 | I18: Day 4 | J18: Day 5 | K18: Day 6 | L18: Day 7
C19: 1. | D19: Date | E19: 40544
C20: 2. | D20: How long did you nap or doze yesterday (in minutes)? | E20: 30
C21: 3. | D21: What time did you get into bed yesterday? | E21: 0.97916667
C22: 4. | D22: What time did you try to go to sleep? | E22: 0.98958333
C23: 5. | D23: How long did it actually take you to fall asleep (in minutes)? | E23: 30
C24: 6. | D24: How many times did you wake up during the night? | E24: 2
C25: 7. | D25: In total, how long did these awakening last (in minutes)? | E25: 60
C26: 8. | D26: What time was your final awakening? | E26: 0.29166667
C27: 9. | D27: When did you get out of bed to start your day? | E27: 0.33333333
C28: 10. | D28: How long did you wakeup earlier than desired (in minutes)? | E28: 30
C29: 11. | D29: How would you rate the quality of your sleep? | E29: Fair
D30: Goal | E30: 0.85 | F30: 0.85 | G30: 0.85 | H30: 0.85 | I30: 0.85 | J30: 0.85 | K30: 0.85 | L30: 0.85
C31: Calculated Results
D32: Time in Bed | E32: =calculations!D202 -> 0.34375 | F32: =calculations!E202 -> 0 | G32: =calculations!F202 -> 0 | H32: =calculations!G202 -> 0 | I32: =calculations!H202 -> 0 | J32: =calculations!I202 -> 0 | K32: =calculations!J202 -> 0 | L32: =calculations!K202 -> 0
D33: Total Sleep Time | E33: =calculations!D203 -> 0.23958333 | F33: =calculations!E203 -> 0 | G33: =calculations!F203 -> 0 | H33: =calculations!G203 -> 0 | I33: =calculations!H203 -> 0 | J33: =calculations!I203 -> 0 | K33: =calculations!J203 -> 0 | L33: =calculations!K203 -> 0
D34: Sleep Efficiency | E34: =calculations!D204 -> 0.6969697 | F34: =calculations!E204 | G34: =calculations!F204 | H34: =calculations!G204 | I34: =calculations!H204 | J34: =calculations!I204 | K34: =calculations!J204 | L34: =calculations!K204
C37: WEEKLY AVERAGES (Will not populate until you have at least 5 sleep diary entries)
D38: Average time napping | E38: =calculations!D208
D39: Average time you got into bed | E39: =calculations!D209
D40: Average time you tried to go to sleep | E40: =calculations!D210
D41: Average time it actually took you to fall asleep | E41: =calculations!D211
D42: Average time of your final awakening | E42: =calculations!D212
D43: Average time you got out of bed to start your day | E43: =calculations!D213
D44: Average time sleeping | E44: =calculations!D214
D45: Average sleep efficiency | E45: =calculations!D215

Sheet calculations
B4: Week 1 | S4: Adjustment items | U4: Rate you sleep
N5: 5-days | O5: 6-days | P5: 7-days | S5: Never | U5: Very Poor
C6: ='Week 1'!C3 -> Sleep Diary Entry for Week 1 | D6: ='Week 1'!E3 -> Sample | E6: ='Week 1'!F3 -> Day 1 | F6: ='Week 1'!G3 -> Day 2 | G6: ='Week 1'!H3 -> Day 3 | H6: ='Week 1'!I3 -> Day 4 | I6: ='Week 1'!J3 -> Day 5 | J6: ='Week 1'!K3 -> Day 6 | K6: ='Week 1'!L3 -> Day 7 | L6: avg | S6: Rarely | U6: Poor
B7: ='Week 1'!C4 -> 1. | C7: ='Week 1'!D4 -> Date | D7: ='Week 1'!E4 -> 40544 | E7: ='Week 1'!F4 -> 39405 | F7: ='Week 1'!G4 -> 0 | G7: ='Week 1'!H4 -> 0 | H7: ='Week 1'!I4 -> 0 | I7: ='Week 1'!J4 -> 0 | ... K7: ='Week 1'!L4 -> 0 | M7: =SUMPRODUCT(--(LEN(E7:K7)>1)) -> 1 | N7: =IF(M7<5,"",IF(D5=5,"Medium",IF(D5="M","Medium","Large"))) | O7: =D30 | S7: Sometimes | U7: Fair
B8: ='Week 1'!C5 -> 2. | C8: ='Week 1'!D5 -> How long did you nap or doze yesterday (in minutes)? | D8: ='Week 1'!E5 -> 30 | E8: ='Week 1'!F5 -> 0 | F8: ='Week 1'!G5 -> 0 | G8: ='Week 1'!H5 -> 0 | H8: ='Week 1'!I5 -> 0 | I8: ='Week 1'!J5 -> 0 | ... K8: ='Week 1'!L5 -> 0 | L8: =SUM(E8:K8)/M7 -> 0 | N8: =SUM(E8:I8)/5 -> 0 | O8: =SUM(E8:J8)/6 -> 0 | P8: =SUM(E8:K8)/7 -> 0 | S8: Frequently | U8: Good
B9: ='Week 1'!C6 -> 3. | C9: ='Week 1'!D6 -> What time did you get into bed yesterday? | D9: ='Week 1'!E6 -> 0.97916667 | E9: ='Week 1'!F6 -> 0.97916667 | F9: ='Week 1'!G6 -> 0 | G9: ='Week 1'!H6 -> 0 | H9: ='Week 1'!I6 -> 0 | I9: ='Week 1'!J6 -> 0 | ... K9: ='Week 1'!L6 -> 0 | L9: =IFERROR(TEXT(IF(L18<0,24+L18,L18)/24,"h:mm"),"") -> 23:30 | N9: =IFERROR(TEXT(IF(N18<0,24+N18,N18)/24,"h:mm"),"") -> 23:54 | O9: =IFERROR(TEXT(IF(O18<0,24+O18,O18)/24,"h:mm"),"") -> 23:55 | P9: =IFERROR(TEXT(IF(P18<0,24+P18,P18)/24,"h:mm"),"") -> 23:55 | S9: Always | U9: Very Good
B10: ='Week 1'!C7 -> 4. | C10: ='Week 1'!D7 -> What time did you try to go to sleep? | D10: ='Week 1'!E7 -> 0.98958333 | E10: ='Week 1'!F7 -> 0.97916667 | F10: ='Week 1'!G7 -> 0 | G10: ='Week 1'!H7 -> 0 | H10: ='Week 1'!I7 -> 0 | I10: ='Week 1'!J7 -> 0 | ... K10: ='Week 1'!L7 -> 0 | L10: =IFERROR(TEXT(IF(L17<0,24+L17,L17)/24,"h:mm"),"") -> 0:00 | N10: =IFERROR(TEXT(IF(N19<0,24+N19,N19)/24,"h:mm"),"") -> 23:54 | O10: =IFERROR(TEXT(IF(O19<0,24+O19,O19)/24,"h:mm"),"") -> 23:55 | P10: =IFERROR(TEXT(IF(P19<0,24+P19,P19)/24,"h:mm"),"") -> 23:55
B11: ='Week 1'!C8 -> 5. | C11: ='Week 1'!D8 -> How long did it actually take you to fall asleep (in minutes)? | D11: ='Week 1'!E8 -> 30 | E11: ='Week 1'!F8 -> 2 | F11: ='Week 1'!G8 -> 0 | G11: ='Week 1'!H8 -> 0 | H11: ='Week 1'!I8 -> 0 | I11: ='Week 1'!J8 -> 0 | ... K11: ='Week 1'!L8 -> 0 | L11: =IFERROR(AVERAGE(E9:K9),"") -> 0.13988095 | N11: =SUM(E11:I11)/5 -> 0.4 | O11: =SUM(E11:J11)/6 -> 0.33333333 | P11: =SUM(E11:K11)/7 -> 0.28571429
B12: ='Week 1'!C9 -> 6. | C12: ='Week 1'!D9 -> How many times did you wake up during the night? | D12: ='Week 1'!E9 -> 2 | E12: ='Week 1'!F9 -> 5 | F12: ='Week 1'!G9 -> 0 | G12: ='Week 1'!H9 -> 0 | H12: ='Week 1'!I9 -> 0 | I12: ='Week 1'!J9 -> 0 | ... K12: ='Week 1'!L9 -> 0 | L12: =IFERROR(AVERAGE(E10:K10),"") -> 0.13988095 | N12: =SUM(E12:I12)/5 -> 1 | O12: =SUM(E12:J12)/6 -> 0.83333333 | P12: =SUM(E12:K12)/7 -> 0.71428571
B13: ='Week 1'!C10 -> 7. | C13: ='Week 1'!D10 -> In total, how long did these awakening last (in minutes)? | D13: ='Week 1'!E10 -> 60 | E13: ='Week 1'!F10 -> 0 | F13: ='Week 1'!G10 -> 0 | G13: ='Week 1'!H10 -> 0 | H13: ='Week 1'!I10 -> 0 | I13: ='Week 1'!J10 -> 0 | ... K13: ='Week 1'!L10 -> 0 | N13: =SUM(E13:I13)/5 -> 0 | O13: =SUM(E13:J13)/6 -> 0 | P13: =SUM(E13:K13)/7 -> 0
B14: ='Week 1'!C11 -> 8. | C14: ='Week 1'!D11 -> What time was your final awakening? | D14: ='Week 1'!E11 -> 0.29166667 | E14: ='Week 1'!F11 -> 0.27083333 | F14: ='Week 1'!G11 -> 0 | G14: ='Week 1'!H11 -> 0 | H14: ='Week 1'!I11 -> 0 | I14: ='Week 1'!J11 -> 0 | ... K14: ='Week 1'!L11 -> 0 | L14: =IFERROR(TEXT(IF(L19<0,24+L19,L19)/24,"h:mm"),"") -> 23:30 | N14: =IFERROR(TEXT(IF(N20<0,24+N20,N20)/24,"h:mm"),"") -> 1:18 | O14: =IFERROR(TEXT(IF(O20<0,24+O20,O20)/24,"h:mm"),"") -> 1:05 | P14: =IFERROR(TEXT(IF(P20<0,24+P20,P20)/24,"h:mm"),"") -> 0:55
B15: ='Week 1'!C12 -> 9. | C15: ='Week 1'!D12 -> When did you get out of bed to start your day? | D15: ='Week 1'!E12 -> 0.33333333 | E15: ='Week 1'!F12 -> 6.3 | F15: ='Week 1'!G12 -> 0 | G15: ='Week 1'!H12 -> 0 | H15: ='Week 1'!I12 -> 0 | I15: ='Week 1'!J12 -> 0 | ... K15: ='Week 1'!L12 -> 0 | L15: =IFERROR(TEXT(IF(L23<0,24+L23,L23)/24,"h:mm"),"") -> 6:58 | N15: =IFERROR(TEXT(IF(N21<0,24+N21,N21)/24,"h:mm"),"") -> 1:26 | O15: =IFERROR(TEXT(IF(O21<0,24+O21,O21)/24,"h:mm"),"") -> 1:12 | P15: =IFERROR(TEXT(IF(P21<0,24+P21,P21)/24,"h:mm"),"") -> 1:01
B16: ='Week 1'!C14 -> 11. | C16: ='Week 1'!D14 -> How would you rate the quality of your sleep? | D16: ='Week 1'!E14 -> Fair | E16: ='Week 1'!F14 -> Fair | F16: ='Week 1'!G14 -> 0 | G16: ='Week 1'!H14 -> 0 | H16: ='Week 1'!I14 -> 0 | I16: ='Week 1'!J14 -> 0 | ... K16: ='Week 1'!L14 -> 0 | N16: =SUM(E16:I16)/5 -> 0 | O16: =SUM(E16:J16)/6 -> 0 | P16: =SUM(E16:K16)/7 -> 0
D18: =IF(ISBLANK(D9),"",IF(HOUR(D9)>12,HOUR(D9)+(MINUTE(D9)/60)-24,HOUR(D9)+(MINUTE(D9)/60))) -> -0.5 | E18: =IF(ISBLANK(E9),"",IF(HOUR(E9)>12,HOUR(E9)+(MINUTE(E9)/60)-24,HOUR(E9)+(MINUTE(E9)/60))) -> -0.5 | F18: =IF(ISBLANK(F9),"",IF(HOUR(F9)>12,HOUR(F9)+(MINUTE(F9)/60)-24,HOUR(F9)+(MINUTE(F9)/60))) -> 0 | G18: =IF(ISBLANK(G9),"",IF(HOUR(G9)>12,HOUR(G9)+(MINUTE(G9)/60)-24,HOUR(G9)+(MINUTE(G9)/60))) -> 0 | H18: =IF(ISBLANK(H9),"",IF(HOUR(H9)>12,HOUR(H9)+(MINUTE(H9)/60)-24,HOUR(H9)+(MINUTE(H9)/60))) -> 0 | I18: =IF(ISBLANK(I9),"",IF(HOUR(I9)>12,HOUR(I9)+(MINUTE(I9)/60)-24,HOUR(I9)+(MINUTE(I9)/60))) -> 0 | J18: =IF(ISBLANK(J9),"",IF(HOUR(J9)>12,HOUR(J9)+(MINUTE(J9)/60)-24,HOUR(J9)+(MINUTE(J9)/60))) -> 0 | K18: =IF(ISBLANK(K9),"",IF(HOUR(K9)>12,HOUR(K9)+(MINUTE(K9)/60)-24,HOUR(K9)+(MINUTE(K9)/60))) -> 0 | L18: =SUM(E18:K18)/$M$7 -> -0.5 | N18: =SUM(E18:I18)/5 -> -0.1 | O18: =SUM(E18:J18)/6 -> -0.083333333 | P18: =SUM(E18:K18)/7 -> -0.071428571
D19: =IF(ISBLANK(D10),"",IF(HOUR(D10)>12,HOUR(D10)+(MINUTE(D10)/60)-24,HOUR(D10)+(MINUTE(D10)/60))) -> -0.25 | E19: =IF(ISBLANK(E10),"",IF(HOUR(E10)>12,HOUR(E10)+(MINUTE(E10)/60)-24,HOUR(E10)+(MINUTE(E10)/60))) -> -0.5 | F19: =IF(ISBLANK(F10),"",IF(HOUR(F10)>12,HOUR(F10)+(MINUTE(F10)/60)-24,HOUR(F10)+(MINUTE(F10)/60))) -> 0 | G19: =IF(ISBLANK(G10),"",IF(HOUR(G10)>12,HOUR(G10)+(MINUTE(G10)/60)-24,HOUR(G10)+(MINUTE(G10)/60))) -> 0 | H19: =IF(ISBLANK(H10),"",IF(HOUR(H10)>12,HOUR(H10)+(MINUTE(H10)/60)-24,HOUR(H10)+(MINUTE(H10)/60))) -> 0 | I19: =IF(ISBLANK(I10),"",IF(HOUR(I10)>12,HOUR(I10)+(MINUTE(I10)/60)-24,HOUR(I10)+(MINUTE(I10)/60))) -> 0 | J19: =IF(ISBLANK(J10),"",IF(HOUR(J10)>12,HOUR(J10)+(MINUTE(J10)/60)-24,HOUR(J10)+(MINUTE(J10)/60))) -> 0 | K19: =IF(ISBLANK(K10),"",IF(HOUR(K10)>12,HOUR(K10)+(MINUTE(K10)/60)-24,HOUR(K10)+(MINUTE(K10)/60))) -> 0 | L19: =SUM(E19:K19)/$M$7 -> -0.5 | N19: =SUM(E19:I19)/5 -> -0.1 | O19: =SUM(E19:J19)/6 -> -0.083333333 | P19: =SUM(E19:K19)/7 -> -0.071428571
D20: =IF(ISBLANK(D14),"",HOUR(D14)+(MINUTE(D14)/60)) -> 7 | E20: =IF(ISBLANK(E14),"",HOUR(E14)+(MINUTE(E14)/60)) -> 6.5 | F20: =IF(ISBLANK(F14),"",HOUR(F14)+(MINUTE(F14)/60)) -> 0 | G20: =IF(ISBLANK(G14),"",HOUR(G14)+(MINUTE(G14)/60)) -> 0 | H20: =IF(ISBLANK(H14),"",HOUR(H14)+(MINUTE(H14)/60)) -> 0 | I20: =IF(ISBLANK(I14),"",HOUR(I14)+(MINUTE(I14)/60)) -> 0 | J20: =IF(ISBLANK(J14),"",HOUR(J14)+(MINUTE(J14)/60)) -> 0 | K20: =IF(ISBLANK(K14),"",HOUR(K14)+(MINUTE(K14)/60)) -> 0 | L20: =SUM(E20:K20)/$M$7 -> 6.5 | N20: =SUM(E20:I20)/5 -> 1.3 | O20: =SUM(E20:J20)/6 -> 1.0833333 | P20: =SUM(E20:K20)/7 -> 0.92857143
D21: =IF(ISBLANK(D15),"",HOUR(D15)+(MINUTE(D15)/60)) -> 8 | E21: =IF(ISBLANK(E15),"",HOUR(E15)+(MINUTE(E15)/60)) -> 7.2 | F21: =IF(ISBLANK(F15),"",HOUR(F15)+(MINUTE(F15)/60)) -> 0 | G21: =IF(ISBLANK(G15),"",HOUR(G15)+(MINUTE(G15)/60)) -> 0 | H21: =IF(ISBLANK(H15),"",HOUR(H15)+(MINUTE(H15)/60)) -> 0 | I21: =IF(ISBLANK(I15),"",HOUR(I15)+(MINUTE(I15)/60)) -> 0 | J21: =IF(ISBLANK(J15),"",HOUR(J15)+(MINUTE(J15)/60)) -> 0 | K21: =IF(ISBLANK(K15),"",HOUR(K15)+(MINUTE(K15)/60)) -> 0 | L21: =SUM(E21:K21)/$M$7 -> 7.2 | N21: =SUM(E21:I21)/5 -> 1.44 | O21: =SUM(E21:J21)/6 -> 1.2 | P21: =SUM(E21:K21)/7 -> 1.0285714
D22: =IF(ISBLANK(D10),"", IF(ISBLANK(D15),"",24*IF(D10>D15,D15+1-D10,D15-D10))) -> 8.25 | E22: =IF(ISBLANK(E10),"", IF(ISBLANK(E15),"",24*IF(E10>E15,E15+1-E10,E15-E10))) -> 127.7 | F22: =IF(ISBLANK(F10),"", IF(ISBLANK(F15),"",24*IF(F10>F15,F15+1-F10,F15-F10))) -> 0 | G22: =IF(ISBLANK(G10),"", IF(ISBLANK(G15),"",24*IF(G10>G15,G15+1-G10,G15-G10))) -> 0 | H22: =IF(ISBLANK(H10),"", IF(ISBLANK(H15),"",24*IF(H10>H15,H15+1-H10,H15-H10))) -> 0 | I22: =IF(ISBLANK(I10),"", IF(ISBLANK(I15),"",24*IF(I10>I15,I15+1-I10,I15-I10))) -> 0 | J22: =IF(ISBLANK(J10),"", IF(ISBLANK(J15),"",24*IF(J10>J15,J15+1-J10,J15-J10))) -> 0 | K22: =IF(ISBLANK(K10),"", IF(ISBLANK(K15),"",24*IF(K10>K15,K15+1-K10,K15-K10))) -> 0 | L22: =SUM(E22:K22)/$M$7 -> 127.7
D23: =IF(ISBLANK(D24),"",(IF(ISBLANK(D11),"",IF(ISBLANK(D13),"",D22-((D11+D13)/60)-(D21-D20))))) -> 5.75 | E23: =IF(ISBLANK(E24),"",(IF(ISBLANK(E11),"",IF(ISBLANK(E13),"",E22-((E11+E13)/60)-(E21-E20))))) -> 126.96667 | F23: =IF(ISBLANK(F24),"",(IF(ISBLANK(F11),"",IF(ISBLANK(F13),"",F22-((F11+F13)/60)-(F21-F20))))) -> 0 | G23: =IF(ISBLANK(G24),"",(IF(ISBLANK(G11),"",IF(ISBLANK(G13),"",G22-((G11+G13)/60)-(G21-G20))))) -> 0 | H23: =IF(ISBLANK(H24),"",(IF(ISBLANK(H11),"",IF(ISBLANK(H13),"",H22-((H11+H13)/60)-(H21-H20))))) -> 0 | I23: =IF(ISBLANK(I24),"",(IF(ISBLANK(I11),"",IF(ISBLANK(I13),"",I22-((I11+I13)/60)-(I21-I20))))) -> 0 | J23: =IF(ISBLANK(J24),"",(IF(ISBLANK(J11),"",IF(ISBLANK(J13),"",J22-((J11+J13)/60)-(J21-J20))))) -> 0 | K23: =IF(ISBLANK(K24),"",(IF(ISBLANK(K11),"",IF(ISBLANK(K13),"",K22-((K11+K13)/60)-(K21-K20))))) -> 0 | L23: =SUM(E23:K23)/$M$7 -> 126.96667
C24: Time in Bed | D24: =IF(ISBLANK(D10),"", IF(ISBLANK(D15),"",IF(D10>D15,D15+1-D10,D15-D10))) -> 0.34375 | E24: =IF(ISBLANK(E10),"", IF(ISBLANK(E15),"",IF(E10>E15,E15+1-E10,E15-E10))) -> 5.3208333 | F24: =IF(ISBLANK(F10),"", IF(ISBLANK(F15),"",IF(F10>F15,F15+1-F10,F15-F10))) -> 0 | G24: =IF(ISBLANK(G10),"", IF(ISBLANK(G15),"",IF(G10>G15,G15+1-G10,G15-G10))) -> 0 | H24: =IF(ISBLANK(H10),"", IF(ISBLANK(H15),"",IF(H10>H15,H15+1-H10,H15-H10))) -> 0 | I24: =IF(ISBLANK(I10),"", IF(ISBLANK(I15),"",IF(I10>I15,I15+1-I10,I15-I10))) -> 0 | J24: =IF(ISBLANK(J10),"", IF(ISBLANK(J15),"",IF(J10>J15,J15+1-J10,J15-J10))) -> 0 | K24: =IF(ISBLANK(K10),"", IF(ISBLANK(K15),"",IF(K10>K15,K15+1-K10,K15-K10))) -> 0 | N24: =SUM(E24:I24)/5 -> 1.0641667 | O24: =SUM(E24:J24)/6 -> 0.88680556 | P24: =SUM(E24:K24)/7 -> 0.76011905
C25: Total Sleep Time | D25: =D23/24 -> 0.23958333 | E25: =E23/24 -> 5.2902778 | F25: =F23/24 -> 0 | G25: =G23/24 -> 0 | H25: =H23/24 -> 0 | I25: =I23/24 -> 0 | J25: =J23/24 -> 0 | K25: =K23/24 -> 0 | N25: =SUM(E25:I25)/5 -> 1.0580556 | O25: =SUM(E25:J25)/6 -> 0.88171296 | P25: =SUM(E25:K25)/7 -> 0.75575397
C26: Sleep Efficiency | D26: =IF(ISERROR(D25/D24),"",IF(ISBLANK(D25),"",D25/D24)) -> 0.6969697 | E26: =IF(ISERROR(E25/E24),"",IF(ISBLANK(E25),"",E25/E24)) -> 0.99425737 | F26: =IF(ISERROR(F25/F24),"",IF(ISBLANK(F25),"",F25/F24)) | G26: =IF(ISERROR(G25/G24),"",IF(ISBLANK(G25),"",G25/G24)) | H26: =IF(ISERROR(H25/H24),"",IF(ISBLANK(H25),"",H25/H24)) | I26: =IF(ISERROR(I25/I24),"",IF(ISBLANK(I25),"",I25/I24)) | J26: =IF(ISERROR(J25/J24),"",IF(ISBLANK(J25),"",J25/J24)) | K26: =IF(ISERROR(K25/K24),"",IF(ISBLANK(K25),"",K25/K24)) | N26: =SUM(E26:I26)/5 -> 0.19885147 | O26: =SUM(E26:J26)/6 -> 0.16570956 | P26: =SUM(E26:K26)/7 -> 0.14203677
B29: WEEKLY AVERAGES | G29: Goal | H29: 0.85
C30: Average time napping. | D30: =IF($M$7<5,"",IF($M$7=5,N8,IF($M$7=6,O8,P8)))
C31: Average time did you got into bed. | D31: =IF($M$7<5,"",IF($M$7=5,N9,IF($M$7=6,O9,P9)))
C32: Average time you tried to go to sleep. | D32: =IF($M$7<5,"",IF($M$7=5,N10,IF($M$7=6,O10,P10)))
C33: Average time it actually took you to fall asleep. | D33: =IF($M$7<5,"",IF($M$7=5,N11,IF($M$7=6,O11,P11)))
C34: Average time of your final awakening. | D34: =IF($M$7<5,"",IF($M$7=5,N14,IF($M$7=6,O14,P14)))
C35: Average time you got out of bed to start your day. | D35: =IF($M$7<5,"",IF($M$7=5,N15,IF($M$7=6,O15,P15)))
C36: Average time sleeping | D36: =IF($M$7<5,"",IF($M$7=5,N25,IF($M$7=6,O25,P25)))
C37: Average sleep efficiency | D37: =IF($M$7<5,"",IF($M$7=5,N26,IF($M$7=6,O26,P26)))
B39: Week 2
N40: 5-days | O40: 6-days | P40: 7-days
B41: ='Week 2'!C12 -> Sleep Diary Entry for Week 2 | C41: ='Week 2'!D12 -> Sleep Diary Entry for Week 2 | D41: ='Week 2'!E12 -> Sample | E41: ='Week 2'!F12 -> Day 1 | F41: ='Week 2'!G12 -> Day 2 | G41: ='Week 2'!H12 -> Day 3 | H41: ='Week 2'!I12 -> Day 4 | I41: ='Week 2'!J12 -> Day 5 | ... L41: ='Week 2'!M12 -> 0 | R41: Sleep Prescription
B42: ='Week 2'!C13 -> 1. | C42: ='Week 2'!D13 -> Date | D42: ='Week 2'!E13 -> 41647 | E42: ='Week 2'!F13 -> 0 | F42: ='Week 2'!G13 -> 0 | G42: ='Week 2'!H13 -> 0 | H42: ='Week 2'!I13 -> 0 | I42: ='Week 2'!J13 -> 0 | ... L42: ='Week 2'!M13 -> 0 | M42: =SUMPRODUCT(--(LEN(E42:K42)>1)) -> 0 | N42: =IF(M42<5,"",IF(D40=5,"Medium",IF(D40="M","Medium","Large"))) | O42: =D65 | R42: Wake Up Time> | S42: ='Week 2'!E4 -> 0.16666667
B43: ='Week 2'!C14 -> 2. | C43: ='Week 2'!D14 -> How long did you nap or doze yesterday (in minutes)? | D43: ='Week 2'!E14 -> 30 | E43: ='Week 2'!F14 -> 0 | F43: ='Week 2'!G14 -> 0 | G43: ='Week 2'!H14 -> 0 | H43: ='Week 2'!I14 -> 0 | I43: ='Week 2'!J14 -> 0 | ... L43: ='Week 2'!M14 -> 0 | N43: =SUM(E43:I43)/5 -> 0 | O43: =SUM(E43:J43)/6 -> 0 | P43: =SUM(E43:K43)/7 -> 0 | R43: TST> | S43: =D36 | T43: =IF(S43+TIME(0,30,0)<0.229166666666667,0.229166666666667,S43+TIME(0,30,0)) -> #VALUE!
B44: ='Week 2'!C15 -> 3. | C44: ='Week 2'!D15 -> What time did you get into bed yesterday? | D44: ='Week 2'!E15 -> 0.97916667 | E44: ='Week 2'!F15 -> 0 | F44: ='Week 2'!G15 -> 0 | G44: ='Week 2'!H15 -> 0 | H44: ='Week 2'!I15 -> 0 | I44: ='Week 2'!J15 -> 0 | ... L44: ='Week 2'!M15 -> 0 | N44: =IFERROR(TEXT(IF(N53<0,24+N53,N53)/24,"h:mm"),"") -> 0:00 | O44: =IFERROR(TEXT(IF(O53<0,24+O53,O53)/24,"h:mm"),"") -> 0:00 | P44: =IFERROR(TEXT(IF(P53<0,24+P53,P53)/24,"h:mm"),"") -> 0:00 | R44: EBT> | S44: =S42-T43 -> #VALUE! | T44: 1
B45: ='Week 2'!C16 -> 4. | C45: ='Week 2'!D16 -> What time did you try to go to sleep? | D45: ='Week 2'!E16 -> 0.98958333 | E45: ='Week 2'!F16 -> 0 | F45: ='Week 2'!G16 -> 0 | G45: ='Week 2'!H16 -> 0 | H45: ='Week 2'!I16 -> 0 | I45: ='Week 2'!J16 -> 0 | ... L45: ='Week 2'!M16 -> 0 | N45: =IFERROR(TEXT(IF(N54<0,24+N54,N54)/24,"h:mm"),"") -> 0:00 | O45: =IFERROR(TEXT(IF(O54<0,24+O54,O54)/24,"h:mm"),"") -> 0:00 | P45: =IFERROR(TEXT(IF(P54<0,24+P54,P54)/24,"h:mm"),"") -> 0:00 | R45: adjust> | S45: =IF((S44)<0,(S44)+T44,(S44)) -> #VALUE!
B46: ='Week 2'!C17 -> 5. | C46: ='Week 2'!D17 -> How long did it actually take you to fall asleep (in minutes)? | D46: ='Week 2'!E17 -> 30 | E46: ='Week 2'!F17 -> 0 | F46: ='Week 2'!G17 -> 0 | G46: ='Week 2'!H17 -> 0 | H46: ='Week 2'!I17 -> 0 | I46: ='Week 2'!J17 -> 0 | ... L46: ='Week 2'!M17 -> 0 | N46: =SUM(E46:I46)/5 -> 0 | O46: =SUM(E46:J46)/6 -> 0 | P46: =SUM(E46:K46)/7 -> 0 | R46: adjust2> | S46: =IF(S43>0.229166666666667,S45+TIME(0,1,0),S45) -> #VALUE!
B47: ='Week 2'!C18 -> 6. | C47: ='Week 2'!D18 -> How many times did you wake up during the night? | D47: ='Week 2'!E18 -> 2 | E47: ='Week 2'!F18 -> 0 | F47: ='Week 2'!G18 -> 0 | G47: ='Week 2'!H18 -> 0 | H47: ='Week 2'!I18 -> 0 | I47: ='Week 2'!J18 -> 0 | ... L47: ='Week 2'!M18 -> 0 | N47: =SUM(E47:I47)/5 -> 0 | O47: =SUM(E47:J47)/6 -> 0 | P47: =SUM(E47:K47)/7 -> 0
...

Sheet examples
B4: Test Data
Q5: 12 AM = 0000 | R5: 12 PM = 1200
C6: Sleep Diary Entry for Week 1 | D6: Sample | E6: Day 1 | F6: Day 2 | G6: Day 3 | H6: Day 4 | I6: Day 5 | J6: Day 6 | K6: Day 7 | Q6: 1 AM = 0100 | R6: 1 PM = 1300
B7: 1. | C7: Date | D7: 40544 | E7: 41689 | F7: 41690 | G7: 41691 | H7: 41692 | I7: 41693 | J7: 41694 | K7: 41696 | Q7: 2 AM = 0200 | R7: 2 PM = 1400
B8: 2. | C8: How long did you nap or doze yesterday (in minutes)? | D8: 30 | E8: 30 | F8: 60 | G8: 40 | H8: 30 | I8: 0 | J8: 0 | K8: 20 | Q8: 3 AM = 0300 | R8: 3 PM = 1500
B9: 3. | C9: What time did you get into bed yesterday? | D9: 0.97916667 | E9: 0.92361111 | F9: 0.95833333 | G9: 0.97222222 | H9: 0.95833333 | I9: 0.91666667 | J9: 0.92361111 | K9: 0.9375 | Q9: 4 AM = 0400 | R9: 4 PM = 1600
B10: 4. | C10: What time did you try to go to sleep? | D10: 0.98958333 | E10: 0.9375 | F10: 0.97222222 | G10: 0.97222222 | H10: 0.97222222 | I10: 0.94444444 | J10: 0.95138889 | K10: 0.94444444 | Q10: 5 AM = 0500 | R10: 5 PM = 1700
B11: 5. | C11: How long did it actually take you to fall asleep (in minutes)? | D11: 30 | E11: 30 | F11: 50 | G11: 90 | H11: 10 | I11: 30 | J11: 20 | K11: 20 | Q11: 6 AM = 0600 | R11: 6 PM = 1800
B12: 6. | C12: How many times did you wake up during the night? | D12: 2 | E12: 3 | F12: 3 | G12: 2 | H12: 0 | I12: 2 | J12: 0 | K12: 2 | Q12: 7 AM = 0700 | R12: 7 PM = 1900
B13: 7. | C13: In total, how long did these awakening last (in minutes)? | D13: 60 | E13: 50 | F13: 90 | G13: 20 | H13: 0 | I13: 50 | J13: 0 | K13: 70 | Q13: 8 AM = 0800 | R13: 8 PM = 2000
B14: 8. | C14: What time was your final awakening? | D14: 0.29166667 | E14: 0.25 | F14: 0.24305556 | G14: 0.25694444 | H14: 0.25 | I14: 0.22916667 | J14: 0.27777778 | K14: 0.27777778 | Q14: 9 AM = 0900 | R14: 9 PM = 2100
B15: 9. | C15: When did you get out of bed to start your day? | D15: 0.33333333 | E15: 0.27083333 | F15: 0.27083333 | G15: 0.26388889 | H15: 0.27083333 | I15: 0.26388889 | J15: 0.29166667 | K15: 0.29166667 | Q15: 10 AM = 1000 | R15: 10 PM = 2200
B16: 10. | C16: How long did you wakeup earlier than desired (in minutes)? | D16: 30 | E16: 30 | F16: 40 | G16: 10 | H16: 30 | I16: 50 | J16: 5 | Q16: 11 AM = 1100 | R16: 11 PM = 2300
B17: 11. | C17: How would you rate the quality of your sleep? | D17: Fair
C22: Sleep Diary Entry for Week 2 | D22: Sample | E22: Day 1 | F22: Day 2 | G22: Day 3 | H22: Day 4 | I22: Day 5 | J22: Day 6 | K22: Day 7
B23: 1. | C23: Date | D23: 40544 | E23: 41383 | F23: 41384 | G23: 41385 | H23: 41386 | I23: 41387 | J23: 41388 | K23: 41389
B24: 2. | C24: How long did you nap or doze yesterday (in minutes)? | D24: 30 | E24: 10 | F24: 20 | G24: 30 | H24: 40 | I24: 50 | J24: 0 | K24: 0
B25: 3. | C25: What time did you get into bed yesterday? | D25: 0.97916667 | E25: 0.92361111 | F25: 0.95833333 | G25: 0.97222222 | H25: 0.95833333 | I25: 0.91666667 | J25: 0.92361111 | K25: 0.9375
B26: 4. | C26: What time did you try to go to sleep? | D26: 0.98958333 | E26: 0.9375 | F26: 0.97222222 | G26: 0.97222222 | H26: 0.97222222 | I26: 0.94444444 | J26: 0.95138889 | K26: 0.94444444
B27: 5. | C27: How long did it actually take you to fall asleep (in minutes)? | D27: 30 | E27: 30 | F27: 50 | G27: 90 | H27: 10 | I27: 30 | J27: 20 | K27: 20
B28: 6. | C28: How many times did you wake up during the night? | D28: 2 | E28: 1 | F28: 2 | G28: 1 | H28: 0 | I28: 2 | J28: 0 | K28: 2
B29: 7. | C29: In total, how long did these awakening last (in minutes)? | D29: 60 | E29: 50 | F29: 90 | G29: 20 | H29: 0 | I29: 50 | J29: 0 | K29: 70
B30: 8. | C30: What time was your final awakening? | D30: 0.29166667 | E30: 0.25 | F30: 0.24305556 | G30: 0.25694444 | H30: 0.25 | I30: 0.22916667 | J30: 0.27777778 | K30: 0.27777778
B31: 9. | C31: When did you get out of bed to start your day? | D31: 0.33333333 | E31: 0.27083333 | F31: 0.27083333 | G31: 0.26388889 | H31: 0.27083333 | I31: 0.26388889 | J31: 0.29166667 | K31: 0.29166667
B32: 10. | C32: How long did you wakeup earlier than desired (in minutes)? | D32: 30 | E32: 30 | F32: 40 | G32: 20 | H32: 30 | I32: 60 | J32: 0 | K32: 0
B33: 11. | C33: How would you rate the quality of your sleep? | D33: Fair
